Workbook
Name lst_TA_decision: 'codes'!$A$2:$A$5
Name lst_TA_reason: 'codes'!$C$2:$C$9
Name lst_TA_reason_table: 'codes'!$C$2:$D$9
Name lst_FT_decision: 'codes'!$F$2:$F$11
Name lst_FT_code: 'codes'!$H$2:$H$9
Name lst_FT_code_table: 'codes'!$H$2:$J$9
Name lst_FT_sci_excl: 'codes'!$L$2:$L$2
Name lst_boolean: 'codes'!$N$2:$N$6
Name lst_TA_binary_map: 'codes'!$P$2:$P$5
Name lst_TA_binary_map_table: 'codes'!$P$2:$Q$5
Name lst_TA_binary: 'codes'!$S$2:$S$3
Name lst_FT_group_map: 'codes'!$U$2:$U$11
Name lst_FT_group_map_table: 'codes'!$U$2:$V$11
Name lst_FT_group: 'codes'!$X$2:$X$4
Name lst_admin_status: 'codes'!$Z$2:$Z$7
Name lst_admin_status_table: 'codes'!$Z$2:$AB$7
Name lst_dedup_duplicate: 'codes'!$AD$2:$AD$3
Name lst_search_id: 'codes'!$AF$2:$AF$17
Name lst_search_id_table: 'codes'!$AF$2:$AI$17
Name lst_database: 'codes'!$AK$2:$AK$9
Name lst_route: 'codes'!$AM$2:$AM$5
Name lst_not_exclusion: 'codes'!$AO$2:$AO$12
Name TA_master_n: 'merge_TA'!$W$4
Name TA_pool_n: 'merge_TA'!$W$5
Name TA_n_A: 'merge_TA'!$W$6
Name TA_n_B: 'merge_TA'!$W$7
Name TA_n_joint: 'merge_TA'!$W$8
Name TA_n_conflict: 'merge_TA'!$W$9
Name TA_n_invalid: 'merge_TA'!$W$10
Name TA_warning: 'merge_TA'!$W$11
Name TA_exact_n: 'merge_TA'!$W$26
Name TA_exact_agree: 'merge_TA'!$W$27
Name TA_exact_po: 'merge_TA'!$W$28
Name TA_exact_pe: 'merge_TA'!$W$29
Name TA_exact_kappa: 'merge_TA'!$W$30
Name TA_binary_n: 'merge_TA'!$W$37
Name TA_binary_agree: 'merge_TA'!$W$38
Name TA_binary_po: 'merge_TA'!$W$39
Name TA_binary_pe: 'merge_TA'!$W$40
Name TA_binary_kappa: 'merge_TA'!$W$41
Name TA_cal_planned: 'merge_TA'!$W$45
Name TA_cal_seed: 'merge_TA'!$W$46
Name TA_cal_round: 'merge_TA'!$W$47
Name TA_cal_round_seed: 'merge_TA'!$W$48
Name TA_cal_threshold: 'merge_TA'!$W$49
Name TA_cal_resolved: 'merge_TA'!$W$50
Name TA_cal_n: 'merge_TA'!$W$115
Name TA_cal_agree: 'merge_TA'!$W$116
Name TA_cal_po: 'merge_TA'!$W$117
Name TA_cal_pe: 'merge_TA'!$W$118
Name TA_cal_kappa: 'merge_TA'!$W$56
Name TA_cal_ids: 'merge_TA'!$W$51
Name TA_cal_notfound: 'merge_TA'!$W$52
Name TA_cal_den: 'merge_TA'!$W$53
Name TA_cal_num: 'merge_TA'!$W$54
Name TA_cal_raw: 'merge_TA'!$W$55
Name TA_cal_status: 'merge_TA'!$W$57
Name FT_master_n: 'merge_FT'!$X$4
Name FT_pool_n: 'merge_FT'!$X$5
Name FT_n_A: 'merge_FT'!$X$6

Sheet README
A1: 筛选工作簿 Screening workbook (blank template — no records, no decisions)
A3: 生成信息 Generation
A4: generated_on | B4: 2026-10-04
A5: generator | B5: scripts/build_workbooks.py v1.0.0
A6: formula rows (--rows) | B6: 5000
A7: conflict list rows | B7: 1000
A8: regenerate | B8: python3 scripts/build_workbooks.py --reviewer A --reviewer B
A9: status | B9: formal_screening_status=NOT_YET_STARTED; screening_counts_status=NOT_YET_AVAILABLE
A11: 源模板版本 Source templates
A12: 04_screening/screening_log_template.json | B12: protocol_version=2.0; protocol_date=2026-10-02; template_status=blank_template_no_formal_screening_results; sha256=cfaf47ba6ba41094…
A13: 04_screening/fulltext_exclusion_codes.json | B13: protocol_version=2.0; protocol_date=2026-10-02; taxonomy_status=predefined_fixed_hierarchy_no_formal_exclusion_results; sha256=9eebf9f76992e9e3…
A14: 04_screening/screening_manual.md | B14: v2.0, 2026-10-02; sha256=eb965c8c80ceacc1…
A15: 04_screening/calibration_plan.md | B15: markdown; sha256=3079ba797e4970d3…
A16: 03_search/search_log_template.json | B16: protocol_version=2.0; protocol_date=2026-10-02; strategy_version=v2.0 / search-draft-0.3; draft_updated=2026-10-03; template_status=DRAFT — NOT EXECUTED; sha256=324d799882afe940…
A17: 05_extraction/data_dictionary.json | B17: metadata.version=2.0; metadata.date=2026-10-02; metadata.schema_verified_date=2026-10-03; sha256=11bd54268fba718a…
A19: 使用步骤 How to use
B20: 1. 数据管理员：撤销 records_master 工作表保护（无密码：审阅→撤销工作表保护），以“仅粘贴数值”导入去重后的正式检索记录（含重复记录行并标注 dedup_status），然后重新保护。不得加入摸底/校准示例记录。
B21: 2. 每位审阅者使用自己的副本，只填写本人 sheet（screen_TA_reviewer_A 或 _B）；锁定本人决定前不得查看对方 sheet。决定列为下拉选择，结构列已锁定。不要排序、插入或删除行：第 n 行与 records_master 第 n 行对应。
B22: 3. 双方锁定后，数据管理员把两份决定合入同一工作簿（复制 decision 等输入列的数值），merge_TA 自动给出一致标记、冲突清单、每人计数、原始一致率与 Cohen kappa；或用 scripts/merge_screening.py 合并两份导出文件。
B23: 4. 校准：merge_TA 中 calibration_50 区块——粘贴按 seed=20261002 抽取的记录号，填写是否全部概念性分歧已解决；通过条件为原始一致率 ≥80% 且分歧全部解决，kappa 仅描述。
B24: 5. 冲突讨论后仍未解决者交预先指定的裁决者（姓名待定，不得虚构）。讨论记录写入 log。
B25: 6. 全文阶段同理：screen_FT_reviewer_A/B → merge_FT。管理状态（重复、未获取、待翻译、待分类、预印本前沿登记）不是科学排除，不填 FT 代码；check_code_rule 列会提示违规。
B26: 7. 任何未执行阶段的计数一律留空或记为 NOT YET AVAILABLE，绝不写 0。
A28: 维护规则 Maintenance rule
B29: 先修改 JSON 模板，再运行脚本重新生成；不得手工修改生成的 xlsx 结构（sheet、列、下拉、保护）。
B30: 工作表保护不设密码，仅用于防止误改结构。
B31: 下拉列表全部来自 codes 工作表，codes 由 JSON 生成。
A33: 模板解释 Interpretations of JSON fields
B34: TA decision list = screening_log_template.field_schema.screening_dispositions filtered to the dispositions printed in bold in screening_manual.md section "B. Title/abstract" (the JSON does not tag dispositions by stage). The task wording "include / exclude / unclear" is implemented with these JSON values: ADVANCE ~ include/progress, EXCLUDE_TA ~ exclude, AWAITING_CLASSIFICATION ~ unclear, FRONTIER_PREPRINT = preprint routing.
B35: FT decision list = all screening_dispositions except the TA-only ones (TA dispositions that are not administrative statuses in fulltext_exclusion_codes.json).
B36: TA primary_reason dropdown re-uses the FT01-FT08 eligibility hierarchy (the manual requires "one primary reason" at TA but defines no separate TA reason codes).
B37: FT primary_exclusion_code dropdown contains only FT01-FT08. The administrative statuses (DUPLICATE_*, NOT_RETRIEVED, AWAITING_*, FRONTIER_PREPRINT) are offered in the FT decision dropdown instead, because screening_log_template record_validation_rules state that administrative statuses require a null primary exclusion code.
B38: Calibration binary grouping (progress / do not exclude vs EXCLUDE_TA) and the 80% raw-agreement threshold are parsed from calibration_plan.md; planned sample size, seed and sampled IDs come from screening_log_template.calibration.
B39: FT agreement is also summarised on a 3-group collapse: INCLUDE (non-administrative, non-exclusion FT dispositions), SCIENTIFIC_EXCLUSION (non-administrative dispositions containing "EXCLUDE"), ADMINISTRATIVE_STATUS (statuses listed in fulltext_exclusion_codes.json). The group labels are formula mechanics, not protocol codes.
B40: dedup_status uses the administrative statuses whose name starts with DUPLICATE; blank means retained/unique (no JSON label exists for a retained record). Rows flagged as duplicates are hidden from the reviewer sheets.
B41: records_master columns: record_id/source/route conventions follow screening_log_template and search_log_template; the bibliographic columns (title, authors, year, journal, doi, pmid, abstract) and dedup_group_id are not defined in any JSON template and follow the task specification.
B42: A_eligible / B_eligible use TRUE/FALSE (JSON booleans) plus NR/NA/UNCLEAR from data_dictionary.json.
B43: FT "page/location" is the JSON field evidence_locations; "supporting passage" and "note" are added columns.
A45: 模板不一致提示 Template issues detected
B46: none detected by the generator

Sheet records_master
A1: record_id | B1: source_database | C1: search_id | D1: route | E1: title | F1: authors | G1: year | H1: journal | I1: doi | J1: pmid | K1: abstract | L1: dedup_group_id | M1: dedup_status | N1: retained_record_id

Sheet screen_TA_reviewer_A
A1: record_id | B1: title | C1: decision | D1: primary_reason | E1: rationale_or_quote | F1: decided_at | G1: note
A2: =IF(OR(records_master!$A2="",ISNUMBER(MATCH(records_master!$M2,lst_dedup_duplicate,0))),"",records_master!$A2) | B2: =IF($A2="","",records_master!$E2)
A3: =IF(OR(records_master!$A3="",ISNUMBER(MATCH(records_master!$M3,lst_dedup_duplicate,0))),"",records_master!$A3) | B3: =IF($A3="","",records_master!$E3)
A4: =IF(OR(records_master!$A4="",ISNUMBER(MATCH(records_master!$M4,lst_dedup_duplicate,0))),"",records_master!$A4) | B4: =IF($A4="","",records_master!$E4)
A5: =IF(OR(records_master!$A5="",ISNUMBER(MATCH(records_master!$M5,lst_dedup_duplicate,0))),"",records_master!$A5) | B5: =IF($A5="","",records_master!$E5)
A6: =IF(OR(records_master!$A6="",ISNUMBER(MATCH(records_master!$M6,lst_dedup_duplicate,0))),"",records_master!$A6) | B6: =IF($A6="","",records_master!$E6)
A7: =IF(OR(records_master!$A7="",ISNUMBER(MATCH(records_master!$M7,lst_dedup_duplicate,0))),"",records_master!$A7) | B7: =IF($A7="","",records_master!$E7)
A8: =IF(OR(records_master!$A8="",ISNUMBER(MATCH(records_master!$M8,lst_dedup_duplicate,0))),"",records_master!$A8) | B8: =IF($A8="","",records_master!$E8)
A9: =IF(OR(records_master!$A9="",ISNUMBER(MATCH(records_master!$M9,lst_dedup_duplicate,0))),"",records_master!$A9) | B9: =IF($A9="","",records_master!$E9)
A10: =IF(OR(records_master!$A10="",ISNUMBER(MATCH(records_master!$M10,lst_dedup_duplicate,0))),"",records_master!$A10) | B10: =IF($A10="","",records_master!$E10)
A11: =IF(OR(records_master!$A11="",ISNUMBER(MATCH(records_master!$M11,lst_dedup_duplicate,0))),"",records_master!$A11) | B11: =IF($A11="","",records_master!$E11)
A12: =IF(OR(records_master!$A12="",ISNUMBER(MATCH(records_master!$M12,lst_dedup_duplicate,0))),"",records_master!$A12) | B12: =IF($A12="","",records_master!$E12)
A13: =IF(OR(records_master!$A13="",ISNUMBER(MATCH(records_master!$M13,lst_dedup_duplicate,0))),"",records_master!$A13) | B13: =IF($A13="","",records_master!$E13)
... A5001: =IF(OR(records_master!$A5001="",ISNUMBER(MATCH(records_master!$M5001,lst_dedup_duplicate,0))),"",records_master!$A5001) | B5001: =IF($A5001="","",records_master!$E5001)

Sheet screen_TA_reviewer_B
A1: record_id | B1: title | C1: decision | D1: primary_reason | E1: rationale_or_quote | F1: decided_at | G1: note
A2: =IF(OR(records_master!$A2="",ISNUMBER(MATCH(records_master!$M2,lst_dedup_duplicate,0))),"",records_master!$A2) | B2: =IF($A2="","",records_master!$E2)
A3: =IF(OR(records_master!$A3="",ISNUMBER(MATCH(records_master!$M3,lst_dedup_duplicate,0))),"",records_master!$A3) | B3: =IF($A3="","",records_master!$E3)
A4: =IF(OR(records_master!$A4="",ISNUMBER(MATCH(records_master!$M4,lst_dedup_duplicate,0))),"",records_master!$A4) | B4: =IF($A4="","",records_master!$E4)
A5: =IF(OR(records_master!$A5="",ISNUMBER(MATCH(records_master!$M5,lst_dedup_duplicate,0))),"",records_master!$A5) | B5: =IF($A5="","",records_master!$E5)
A6: =IF(OR(records_master!$A6="",ISNUMBER(MATCH(records_master!$M6,lst_dedup_duplicate,0))),"",records_master!$A6) | B6: =IF($A6="","",records_master!$E6)
A7: =IF(OR(records_master!$A7="",ISNUMBER(MATCH(records_master!$M7,lst_dedup_duplicate,0))),"",records_master!$A7) | B7: =IF($A7="","",records_master!$E7)
A8: =IF(OR(records_master!$A8="",ISNUMBER(MATCH(records_master!$M8,lst_dedup_duplicate,0))),"",records_master!$A8) | B8: =IF($A8="","",records_master!$E8)
A9: =IF(OR(records_master!$A9="",ISNUMBER(MATCH(records_master!$M9,lst_dedup_duplicate,0))),"",records_master!$A9) | B9: =IF($A9="","",records_master!$E9)
A10: =IF(OR(records_master!$A10="",ISNUMBER(MATCH(records_master!$M10,lst_dedup_duplicate,0))),"",records_master!$A10) | B10: =IF($A10="","",records_master!$E10)
A11: =IF(OR(records_master!$A11="",ISNUMBER(MATCH(records_master!$M11,lst_dedup_duplicate,0))),"",records_master!$A11) | B11: =IF($A11="","",records_master!$E11)
A12: =IF(OR(records_master!$A12="",ISNUMBER(MATCH(records_master!$M12,lst_dedup_duplicate,0))),"",records_master!$A12) | B12: =IF($A12="","",records_master!$E12)
A13: =IF(OR(records_master!$A13="",ISNUMBER(MATCH(records_master!$M13,lst_dedup_duplicate,0))),"",records_master!$A13) | B13: =IF($A13="","",records_master!$E13)
... A5001: =IF(OR(records_master!$A5001="",ISNUMBER(MATCH(records_master!$M5001,lst_dedup_duplicate,0))),"",records_master!$A5001) | B5001: =IF($A5001="","",records_master!$E5001)

Sheet screen_FT_reviewer_A
A1: record_id | B1: title | C1: decision | D1: primary_exclusion_code | E1: secondary_failed_dimensions | F1: A_eligible | G1: B_eligible | H1: evidence_locations | I1: rationale | J1: decided_at | K1: supporting_passage | L1: note | M1: check_code_rule
A2: =IF(OR(records_master!$A2="",ISNUMBER(MATCH(records_master!$M2,lst_dedup_duplicate,0))),"",records_master!$A2) | B2: =IF($A2="","",records_master!$E2) | M2: =IF($A2="","",IF(AND(ISNUMBER(MATCH(C2,lst_FT_sci_excl,0)),D2=""),"MISSING FT CODE",IF(AND(NOT(ISNUMBER(MATCH(C2,lst_FT_sci_excl,0))),D2<>""),"CODE NOT ALLOWED FOR THIS DECISION","")))
A3: =IF(OR(records_master!$A3="",ISNUMBER(MATCH(records_master!$M3,lst_dedup_duplicate,0))),"",records_master!$A3) | B3: =IF($A3="","",records_master!$E3) | M3: =IF($A3="","",IF(AND(ISNUMBER(MATCH(C3,lst_FT_sci_excl,0)),D3=""),"MISSING FT CODE",IF(AND(NOT(ISNUMBER(MATCH(C3,lst_FT_sci_excl,0))),D3<>""),"CODE NOT ALLOWED FOR THIS DECISION","")))
A4: =IF(OR(records_master!$A4="",ISNUMBER(MATCH(records_master!$M4,lst_dedup_duplicate,0))),"",records_master!$A4) | B4: =IF($A4="","",records_master!$E4) | M4: =IF($A4="","",IF(AND(ISNUMBER(MATCH(C4,lst_FT_sci_excl,0)),D4=""),"MISSING FT CODE",IF(AND(NOT(ISNUMBER(MATCH(C4,lst_FT_sci_excl,0))),D4<>""),"CODE NOT ALLOWED FOR THIS DECISION","")))
A5: =IF(OR(records_master!$A5="",ISNUMBER(MATCH(records_master!$M5,lst_dedup_duplicate,0))),"",records_master!$A5) | B5: =IF($A5="","",records_master!$E5) | M5: =IF($A5="","",IF(AND(ISNUMBER(MATCH(C5,lst_FT_sci_excl,0)),D5=""),"MISSING FT CODE",IF(AND(NOT(ISNUMBER(MATCH(C5,lst_FT_sci_excl,0))),D5<>""),"CODE NOT ALLOWED FOR THIS DECISION","")))
A6: =IF(OR(records_master!$A6="",ISNUMBER(MATCH(records_master!$M6,lst_dedup_duplicate,0))),"",records_master!$A6) | B6: =IF($A6="","",records_master!$E6) | M6: =IF($A6="","",IF(AND(ISNUMBER(MATCH(C6,lst_FT_sci_excl,0)),D6=""),"MISSING FT CODE",IF(AND(NOT(ISNUMBER(MATCH(C6,lst_FT_sci_excl,0))),D6<>""),"CODE NOT ALLOWED FOR THIS DECISION","")))
A7: =IF(OR(records_master!$A7="",ISNUMBER(MATCH(records_master!$M7,lst_dedup_duplicate,0))),"",records_master!$A7) | B7: =IF($A7="","",records_master!$E7) | M7: =IF($A7="","",IF(AND(ISNUMBER(MATCH(C7,lst_FT_sci_excl,0)),D7=""),"MISSING FT CODE",IF(AND(NOT(ISNUMBER(MATCH(C7,lst_FT_sci_excl,0))),D7<>""),"CODE NOT ALLOWED FOR THIS DECISION","")))
A8: =IF(OR(records_master!$A8="",ISNUMBER(MATCH(records_master!$M8,lst_dedup_duplicate,0))),"",records_master!$A8) | B8: =IF($A8="","",records_master!$E8) | M8: =IF($A8="","",IF(AND(ISNUMBER(MATCH(C8,lst_FT_sci_excl,0)),D8=""),"MISSING FT CODE",IF(AND(NOT(ISNUMBER(MATCH(C8,lst_FT_sci_excl,0))),D8<>""),"CODE NOT ALLOWED FOR THIS DECISION","")))
A9: =IF(OR(records_master!$A9="",ISNUMBER(MATCH(records_master!$M9,lst_dedup_duplicate,0))),"",records_master!$A9) | B9: =IF($A9="","",records_master!$E9) | M9: =IF($A9="","",IF(AND(ISNUMBER(MATCH(C9,lst_FT_sci_excl,0)),D9=""),"MISSING FT CODE",IF(AND(NOT(ISNUMBER(MATCH(C9,lst_FT_sci_excl,0))),D9<>""),"CODE NOT ALLOWED FOR THIS DECISION","")))
A10: =IF(OR(records_master!$A10="",ISNUMBER(MATCH(records_master!$M10,lst_dedup_duplicate,0))),"",records_master!$A10) | B10: =IF($A10="","",records_master!$E10) | M10: =IF($A10="","",IF(AND(ISNUMBER(MATCH(C10,lst_FT_sci_excl,0)),D10=""),"MISSING FT CODE",IF(AND(NOT(ISNUMBER(MATCH(C10,lst_FT_sci_excl,0))),D10<>""),"CODE NOT ALLOWED FOR THIS DECISION","")))
A11: =IF(OR(records_master!$A11="",ISNUMBER(MATCH(records_master!$M11,lst_dedup_duplicate,0))),"",records_master!$A11) | B11: =IF($A11="","",records_master!$E11) | M11: =IF($A11="","",IF(AND(ISNUMBER(MATCH(C11,lst_FT_sci_excl,0)),D11=""),"MISSING FT CODE",IF(AND(NOT(ISNUMBER(MATCH(C11,lst_FT_sci_excl,0))),D11<>""),"CODE NOT ALLOWED FOR THIS DECISION","")))
A12: =IF(OR(records_master!$A12="",ISNUMBER(MATCH(records_master!$M12,lst_dedup_duplicate,0))),"",records_master!$A12) | B12: =IF($A12="","",records_master!$E12) | M12: =IF($A12="","",IF(AND(ISNUMBER(MATCH(C12,lst_FT_sci_excl,0)),D12=""),"MISSING FT CODE",IF(AND(NOT(ISNUMBER(MATCH(C12,lst_FT_sci_excl,0))),D12<>""),"CODE NOT ALLOWED FOR THIS DECISION","")))
A13: =IF(OR(records_master!$A13="",ISNUMBER(MATCH(records_master!$M13,lst_dedup_duplicate,0))),"",records_master!$A13) | B13: =IF($A13="","",records_master!$E13) | M13: =IF($A13="","",IF(AND(ISNUMBER(MATCH(C13,lst_FT_sci_excl,0)),D13=""),"MISSING FT CODE",IF(AND(NOT(ISNUMBER(MATCH(C13,lst_FT_sci_excl,0))),D13<>""),"CODE NOT ALLOWED FOR THIS DECISION","")))
... A5001: =IF(OR(records_master!$A5001="",ISNUMBER(MATCH(records_master!$M5001,lst_dedup_duplicate,0))),"",records_master!$A5001) | B5001: =IF($A5001="","",records_master!$E5001) | M5001: =IF($A5001="","",IF(AND(ISNUMBER(MATCH(C5001,lst_FT_sci_excl,0)),D5001=""),"MISSING FT CODE",IF(AND(NOT(ISNUMBER(MATCH(C5001,lst_FT_sci_excl,0))),D5001<>""),"CODE NOT ALLOWED FOR THIS DECISION","")))

Sheet screen_FT_reviewer_B
A1: record_id | B1: title | C1: decision | D1: primary_exclusion_code | E1: secondary_failed_dimensions | F1: A_eligible | G1: B_eligible | H1: evidence_locations | I1: rationale | J1: decided_at | K1: supporting_passage | L1: note | M1: check_code_rule
A2: =IF(OR(records_master!$A2="",ISNUMBER(MATCH(records_master!$M2,lst_dedup_duplicate,0))),"",records_master!$A2) | B2: =IF($A2="","",records_master!$E2) | M2: =IF($A2="","",IF(AND(ISNUMBER(MATCH(C2,lst_FT_sci_excl,0)),D2=""),"MISSING FT CODE",IF(AND(NOT(ISNUMBER(MATCH(C2,lst_FT_sci_excl,0))),D2<>""),"CODE NOT ALLOWED FOR THIS DECISION","")))
A3: =IF(OR(records_master!$A3="",ISNUMBER(MATCH(records_master!$M3,lst_dedup_duplicate,0))),"",records_master!$A3) | B3: =IF($A3="","",records_master!$E3) | M3: =IF($A3="","",IF(AND(ISNUMBER(MATCH(C3,lst_FT_sci_excl,0)),D3=""),"MISSING FT CODE",IF(AND(NOT(ISNUMBER(MATCH(C3,lst_FT_sci_excl,0))),D3<>""),"CODE NOT ALLOWED FOR THIS DECISION","")))
A4: =IF(OR(records_master!$A4="",ISNUMBER(MATCH(records_master!$M4,lst_dedup_duplicate,0))),"",records_master!$A4) | B4: =IF($A4="","",records_master!$E4) | M4: =IF($A4="","",IF(AND(ISNUMBER(MATCH(C4,lst_FT_sci_excl,0)),D4=""),"MISSING FT CODE",IF(AND(NOT(ISNUMBER(MATCH(C4,lst_FT_sci_excl,0))),D4<>""),"CODE NOT ALLOWED FOR THIS DECISION","")))
A5: =IF(OR(records_master!$A5="",ISNUMBER(MATCH(records_master!$M5,lst_dedup_duplicate,0))),"",records_master!$A5) | B5: =IF($A5="","",records_master!$E5) | M5: =IF($A5="","",IF(AND(ISNUMBER(MATCH(C5,lst_FT_sci_excl,0)),D5=""),"MISSING FT CODE",IF(AND(NOT(ISNUMBER(MATCH(C5,lst_FT_sci_excl,0))),D5<>""),"CODE NOT ALLOWED FOR THIS DECISION","")))
A6: =IF(OR(records_master!$A6="",ISNUMBER(MATCH(records_master!$M6,lst_dedup_duplicate,0))),"",records_master!$A6) | B6: =IF($A6="","",records_master!$E6) | M6: =IF($A6="","",IF(AND(ISNUMBER(MATCH(C6,lst_FT_sci_excl,0)),D6=""),"MISSING FT CODE",IF(AND(NOT(ISNUMBER(MATCH(C6,lst_FT_sci_excl,0))),D6<>""),"CODE NOT ALLOWED FOR THIS DECISION","")))
A7: =IF(OR(records_master!$A7="",ISNUMBER(MATCH(records_master!$M7,lst_dedup_duplicate,0))),"",records_master!$A7) | B7: =IF($A7="","",records_master!$E7) | M7: =IF($A7="","",IF(AND(ISNUMBER(MATCH(C7,lst_FT_sci_excl,0)),D7=""),"MISSING FT CODE",IF(AND(NOT(ISNUMBER(MATCH(C7,lst_FT_sci_excl,0))),D7<>""),"CODE NOT ALLOWED FOR THIS DECISION","")))
A8: =IF(OR(records_master!$A8="",ISNUMBER(MATCH(records_master!$M8,lst_dedup_duplicate,0))),"",records_master!$A8) | B8: =IF($A8="","",records_master!$E8) | M8: =IF($A8="","",IF(AND(ISNUMBER(MATCH(C8,lst_FT_sci_excl,0)),D8=""),"MISSING FT CODE",IF(AND(NOT(ISNUMBER(MATCH(C8,lst_FT_sci_excl,0))),D8<>""),"CODE NOT ALLOWED FOR THIS DECISION","")))
A9: =IF(OR(records_master!$A9="",ISNUMBER(MATCH(records_master!$M9,lst_dedup_duplicate,0))),"",records_master!$A9) | B9: =IF($A9="","",records_master!$E9) | M9: =IF($A9="","",IF(AND(ISNUMBER(MATCH(C9,lst_FT_sci_excl,0)),D9=""),"MISSING FT CODE",IF(AND(NOT(ISNUMBER(MATCH(C9,lst_FT_sci_excl,0))),D9<>""),"CODE NOT ALLOWED FOR THIS DECISION","")))
A10: =IF(OR(records_master!$A10="",ISNUMBER(MATCH(records_master!$M10,lst_dedup_duplicate,0))),"",records_master!$A10) | B10: =IF($A10="","",records_master!$E10) | M10: =IF($A10="","",IF(AND(ISNUMBER(MATCH(C10,lst_FT_sci_excl,0)),D10=""),"MISSING FT CODE",IF(AND(NOT(ISNUMBER(MATCH(C10,lst_FT_sci_excl,0))),D10<>""),"CODE NOT ALLOWED FOR THIS DECISION","")))
A11: =IF(OR(records_master!$A11="",ISNUMBER(MATCH(records_master!$M11,lst_dedup_duplicate,0))),"",records_master!$A11) | B11: =IF($A11="","",records_master!$E11) | M11: =IF($A11="","",IF(AND(ISNUMBER(MATCH(C11,lst_FT_sci_excl,0)),D11=""),"MISSING FT CODE",IF(AND(NOT(ISNUMBER(MATCH(C11,lst_FT_sci_excl,0))),D11<>""),"CODE NOT ALLOWED FOR THIS DECISION","")))
A12: =IF(OR(records_master!$A12="",ISNUMBER(MATCH(records_master!$M12,lst_dedup_duplicate,0))),"",records_master!$A12) | B12: =IF($A12="","",records_master!$E12) | M12: =IF($A12="","",IF(AND(ISNUMBER(MATCH(C12,lst_FT_sci_excl,0)),D12=""),"MISSING FT CODE",IF(AND(NOT(ISNUMBER(MATCH(C12,lst_FT_sci_excl,0))),D12<>""),"CODE NOT ALLOWED FOR THIS DECISION","")))
A13: =IF(OR(records_master!$A13="",ISNUMBER(MATCH(records_master!$M13,lst_dedup_duplicate,0))),"",records_master!$A13) | B13: =IF($A13="","",records_master!$E13) | M13: =IF($A13="","",IF(AND(ISNUMBER(MATCH(C13,lst_FT_sci_excl,0)),D13=""),"MISSING FT CODE",IF(AND(NOT(ISNUMBER(MATCH(C13,lst_FT_sci_excl,0))),D13<>""),"CODE NOT ALLOWED FOR THIS DECISION","")))
... A5001: =IF(OR(records_master!$A5001="",ISNUMBER(MATCH(records_master!$M5001,lst_dedup_duplicate,0))),"",records_master!$A5001) | B5001: =IF($A5001="","",records_master!$E5001) | M5001: =IF($A5001="","",IF(AND(ISNUMBER(MATCH(C5001,lst_FT_sci_excl,0)),D5001=""),"MISSING FT CODE",IF(AND(NOT(ISNUMBER(MATCH(C5001,lst_FT_sci_excl,0))),D5001<>""),"CODE NOT ALLOWED FOR THIS DECISION","")))

Sheet merge_TA
A1: record_id | B1: decision_A | C1: decision_B | D1: primary_reason_A | E1: primary_reason_B | F1: both_decided | G1: exact_agree | H1: binary_A | I1: binary_B | J1: binary_agree | K1: conflict | L1: conflict_seq | N1: conflict_no | O1: row_in_table | P1: record_id | Q1: decision_A | R1: decision_B | S1: primary_reason_A | T1: primary_reason_B | V1: SUMMARY merge_TA (worksheet formulas; do not edit)
A2: =IF(screen_TA_reviewer_A!$A2="","",screen_TA_reviewer_A!$A2) | B2: =IF(OR($A2="",screen_TA_reviewer_A!$C2=""),"",screen_TA_reviewer_A!$C2) | C2: =IF(OR($A2="",screen_TA_reviewer_B!$C2=""),"",screen_TA_reviewer_B!$C2) | D2: =IF(OR($A2="",screen_TA_reviewer_A!$D2=""),"",screen_TA_reviewer_A!$D2) | E2: =IF(OR($A2="",screen_TA_reviewer_B!$D2=""),"",screen_TA_reviewer_B!$D2) | F2: =IF(AND(B2<>"",C2<>""),1,"") | G2: =IF(F2=1,IF(B2=C2,1,0),"") | H2: =IF(B2="","",IFERROR(VLOOKUP(B2,lst_TA_binary_map_table,2,FALSE),"INVALID")) | I2: =IF(C2="","",IFERROR(VLOOKUP(C2,lst_TA_binary_map_table,2,FALSE),"INVALID")) | J2: =IF(F2=1,IF(H2=I2,1,0),"") | K2: =IF(G2=0,1,"") | L2: =IF(K2=1,COUNTIF($K$2:K2,1),"") | N2: 1 | O2: =IFERROR(MATCH(N2,$L$2:$L$5001,0),"") | P2: =IF(O2="","",INDEX($A$2:$A$5001,O2)) | Q2: =IF(O2="","",INDEX($B$2:$B$5001,O2)) | R2: =IF(O2="","",INDEX($C$2:$C$5001,O2)) | S2: =IF(O2="","",INDEX($D$2:$D$5001,O2)) | T2: =IF(O2="","",INDEX($E$2:$E$5001,O2)) | V2: Pass rule (calibration_plan.md): raw agreement on binary progress / do not exclude vs EXCLUDE_TA ≥ 80% AND every conceptual disagreement resolved. Kappa is descriptive only.
A3: =IF(screen_TA_reviewer_A!$A3="","",screen_TA_reviewer_A!$A3) | B3: =IF(OR($A3="",screen_TA_reviewer_A!$C3=""),"",screen_TA_reviewer_A!$C3) | C3: =IF(OR($A3="",screen_TA_reviewer_B!$C3=""),"",screen_TA_reviewer_B!$C3) | D3: =IF(OR($A3="",screen_TA_reviewer_A!$D3=""),"",screen_TA_reviewer_A!$D3) | E3: =IF(OR($A3="",screen_TA_reviewer_B!$D3=""),"",screen_TA_reviewer_B!$D3) | F3: =IF(AND(B3<>"",C3<>""),1,"") | G3: =IF(F3=1,IF(B3=C3,1,0),"") | H3: =IF(B3="","",IFERROR(VLOOKUP(B3,lst_TA_binary_map_table,2,FALSE),"INVALID")) | I3: =IF(C3="","",IFERROR(VLOOKUP(C3,lst_TA_binary_map_table,2,FALSE),"INVALID")) | J3: =IF(F3=1,IF(H3=I3,1,0),"") | K3: =IF(G3=0,1,"") | L3: =IF(K3=1,COUNTIF($K$2:K3,1),"") | N3: 2 | O3: =IFERROR(MATCH(N3,$L$2:$L$5001,0),"") | P3: =IF(O3="","",INDEX($A$2:$A$5001,O3)) | Q3: =IF(O3="","",INDEX($B$2:$B$5001,O3)) | R3: =IF(O3="","",INDEX($C$2:$C$5001,O3)) | S3: =IF(O3="","",INDEX($D$2:$D$5001,O3)) | T3: =IF(O3="","",INDEX($E$2:$E$5001,O3))
A4: =IF(screen_TA_reviewer_A!$A4="","",screen_TA_reviewer_A!$A4) | B4: =IF(OR($A4="",screen_TA_reviewer_A!$C4=""),"",screen_TA_reviewer_A!$C4) | C4: =IF(OR($A4="",screen_TA_reviewer_B!$C4=""),"",screen_TA_reviewer_B!$C4) | D4: =IF(OR($A4="",screen_TA_reviewer_A!$D4=""),"",screen_TA_reviewer_A!$D4) | E4: =IF(OR($A4="",screen_TA_reviewer_B!$D4=""),"",screen_TA_reviewer_B!$D4) | F4: =IF(AND(B4<>"",C4<>""),1,"") | G4: =IF(F4=1,IF(B4=C4,1,0),"") | H4: =IF(B4="","",IFERROR(VLOOKUP(B4,lst_TA_binary_map_table,2,FALSE),"INVALID")) | I4: =IF(C4="","",IFERROR(VLOOKUP(C4,lst_TA_binary_map_table,2,FALSE),"INVALID")) | J4: =IF(F4=1,IF(H4=I4,1,0),"") | K4: =IF(G4=0,1,"") | L4: =IF(K4=1,COUNTIF($K$2:K4,1),"") | N4: 3 | O4: =IFERROR(MATCH(N4,$L$2:$L$5001,0),"") | P4: =IF(O4="","",INDEX($A$2:$A$5001,O4)) | Q4: =IF(O4="","",INDEX($B$2:$B$5001,O4)) | R4: =IF(O4="","",INDEX($C$2:$C$5001,O4)) | S4: =IF(O4="","",INDEX($D$2:$D$5001,O4)) | T4: =IF(O4="","",INDEX($E$2:$E$5001,O4)) | V4: records in records_master (non-blank record_id) | W4: =SUMPRODUCT(--(records_master!$A$2:$A$5001<>""))
A5: =IF(screen_TA_reviewer_A!$A5="","",screen_TA_reviewer_A!$A5) | B5: =IF(OR($A5="",screen_TA_reviewer_A!$C5=""),"",screen_TA_reviewer_A!$C5) | C5: =IF(OR($A5="",screen_TA_reviewer_B!$C5=""),"",screen_TA_reviewer_B!$C5) | D5: =IF(OR($A5="",screen_TA_reviewer_A!$D5=""),"",screen_TA_reviewer_A!$D5) | E5: =IF(OR($A5="",screen_TA_reviewer_B!$D5=""),"",screen_TA_reviewer_B!$D5) | F5: =IF(AND(B5<>"",C5<>""),1,"") | G5: =IF(F5=1,IF(B5=C5,1,0),"") | H5: =IF(B5="","",IFERROR(VLOOKUP(B5,lst_TA_binary_map_table,2,FALSE),"INVALID")) | I5: =IF(C5="","",IFERROR(VLOOKUP(C5,lst_TA_binary_map_table,2,FALSE),"INVALID")) | J5: =IF(F5=1,IF(H5=I5,1,0),"") | K5: =IF(G5=0,1,"") | L5: =IF(K5=1,COUNTIF($K$2:K5,1),"") | N5: 4 | O5: =IFERROR(MATCH(N5,$L$2:$L$5001,0),"") | P5: =IF(O5="","",INDEX($A$2:$A$5001,O5)) | Q5: =IF(O5="","",INDEX($B$2:$B$5001,O5)) | R5: =IF(O5="","",INDEX($C$2:$C$5001,O5)) | S5: =IF(O5="","",INDEX($D$2:$D$5001,O5)) | T5: =IF(O5="","",INDEX($E$2:$E$5001,O5)) | V5: records available to screen (duplicates hidden) | W5: =SUMPRODUCT(--($A$2:$A$5001<>""))
A6: =IF(screen_TA_reviewer_A!$A6="","",screen_TA_reviewer_A!$A6) | B6: =IF(OR($A6="",screen_TA_reviewer_A!$C6=""),"",screen_TA_reviewer_A!$C6) | C6: =IF(OR($A6="",screen_TA_reviewer_B!$C6=""),"",screen_TA_reviewer_B!$C6) | D6: =IF(OR($A6="",screen_TA_reviewer_A!$D6=""),"",screen_TA_reviewer_A!$D6) | E6: =IF(OR($A6="",screen_TA_reviewer_B!$D6=""),"",screen_TA_reviewer_B!$D6) | F6: =IF(AND(B6<>"",C6<>""),1,"") | G6: =IF(F6=1,IF(B6=C6,1,0),"") | H6: =IF(B6="","",IFERROR(VLOOKUP(B6,lst_TA_binary_map_table,2,FALSE),"INVALID")) | I6: =IF(C6="","",IFERROR(VLOOKUP(C6,lst_TA_binary_map_table,2,FALSE),"INVALID")) | J6: =IF(F6=1,IF(H6=I6,1,0),"") | K6: =IF(G6=0,1,"") | L6: =IF(K6=1,COUNTIF($K$2:K6,1),"") | N6: 5 | O6: =IFERROR(MATCH(N6,$L$2:$L$5001,0),"") | P6: =IF(O6="","",INDEX($A$2:$A$5001,O6)) | Q6: =IF(O6="","",INDEX($B$2:$B$5001,O6)) | R6: =IF(O6="","",INDEX($C$2:$C$5001,O6)) | S6: =IF(O6="","",INDEX($D$2:$D$5001,O6)) | T6: =IF(O6="","",INDEX($E$2:$E$5001,O6)) | V6: decided by reviewer A | W6: =SUMPRODUCT(--($B$2:$B$5001<>""))
A7: =IF(screen_TA_reviewer_A!$A7="","",screen_TA_reviewer_A!$A7) | B7: =IF(OR($A7="",screen_TA_reviewer_A!$C7=""),"",screen_TA_reviewer_A!$C7) | C7: =IF(OR($A7="",screen_TA_reviewer_B!$C7=""),"",screen_TA_reviewer_B!$C7) | D7: =IF(OR($A7="",screen_TA_reviewer_A!$D7=""),"",screen_TA_reviewer_A!$D7) | E7: =IF(OR($A7="",screen_TA_reviewer_B!$D7=""),"",screen_TA_reviewer_B!$D7) | F7: =IF(AND(B7<>"",C7<>""),1,"") | G7: =IF(F7=1,IF(B7=C7,1,0),"") | H7: =IF(B7="","",IFERROR(VLOOKUP(B7,lst_TA_binary_map_table,2,FALSE),"INVALID")) | I7: =IF(C7="","",IFERROR(VLOOKUP(C7,lst_TA_binary_map_table,2,FALSE),"INVALID")) | J7: =IF(F7=1,IF(H7=I7,1,0),"") | K7: =IF(G7=0,1,"") | L7: =IF(K7=1,COUNTIF($K$2:K7,1),"") | N7: 6 | O7: =IFERROR(MATCH(N7,$L$2:$L$5001,0),"") | P7: =IF(O7="","",INDEX($A$2:$A$5001,O7)) | Q7: =IF(O7="","",INDEX($B$2:$B$5001,O7)) | R7: =IF(O7="","",INDEX($C$2:$C$5001,O7)) | S7: =IF(O7="","",INDEX($D$2:$D$5001,O7)) | T7: =IF(O7="","",INDEX($E$2:$E$5001,O7)) | V7: decided by reviewer B | W7: =SUMPRODUCT(--($C$2:$C$5001<>""))
A8: =IF(screen_TA_reviewer_A!$A8="","",screen_TA_reviewer_A!$A8) | B8: =IF(OR($A8="",screen_TA_reviewer_A!$C8=""),"",screen_TA_reviewer_A!$C8) | C8: =IF(OR($A8="",screen_TA_reviewer_B!$C8=""),"",screen_TA_reviewer_B!$C8) | D8: =IF(OR($A8="",screen_TA_reviewer_A!$D8=""),"",screen_TA_reviewer_A!$D8) | E8: =IF(OR($A8="",screen_TA_reviewer_B!$D8=""),"",screen_TA_reviewer_B!$D8) | F8: =IF(AND(B8<>"",C8<>""),1,"") | G8: =IF(F8=1,IF(B8=C8,1,0),"") | H8: =IF(B8="","",IFERROR(VLOOKUP(B8,lst_TA_binary_map_table,2,FALSE),"INVALID")) | I8: =IF(C8="","",IFERROR(VLOOKUP(C8,lst_TA_binary_map_table,2,FALSE),"INVALID")) | J8: =IF(F8=1,IF(H8=I8,1,0),"") | K8: =IF(G8=0,1,"") | L8: =IF(K8=1,COUNTIF($K$2:K8,1),"") | N8: 7 | O8: =IFERROR(MATCH(N8,$L$2:$L$5001,0),"") | P8: =IF(O8="","",INDEX($A$2:$A$5001,O8)) | Q8: =IF(O8="","",INDEX($B$2:$B$5001,O8)) | R8: =IF(O8="","",INDEX($C$2:$C$5001,O8)) | S8: =IF(O8="","",INDEX($D$2:$D$5001,O8)) | T8: =IF(O8="","",INDEX($E$2:$E$5001,O8)) | V8: jointly decided | W8: =SUM($F$2:$F$5001)
A9: =IF(screen_TA_reviewer_A!$A9="","",screen_TA_reviewer_A!$A9) | B9: =IF(OR($A9="",screen_TA_reviewer_A!$C9=""),"",screen_TA_reviewer_A!$C9) | C9: =IF(OR($A9="",screen_TA_reviewer_B!$C9=""),"",screen_TA_reviewer_B!$C9) | D9: =IF(OR($A9="",screen_TA_reviewer_A!$D9=""),"",screen_TA_reviewer_A!$D9) | E9: =IF(OR($A9="",screen_TA_reviewer_B!$D9=""),"",screen_TA_reviewer_B!$D9) | F9: =IF(AND(B9<>"",C9<>""),1,"") | G9: =IF(F9=1,IF(B9=C9,1,0),"") | H9: =IF(B9="","",IFERROR(VLOOKUP(B9,lst_TA_binary_map_table,2,FALSE),"INVALID")) | I9: =IF(C9="","",IFERROR(VLOOKUP(C9,lst_TA_binary_map_table,2,FALSE),"INVALID")) | J9: =IF(F9=1,IF(H9=I9,1,0),"") | K9: =IF(G9=0,1,"") | L9: =IF(K9=1,COUNTIF($K$2:K9,1),"") | N9: 8 | O9: =IFERROR(MATCH(N9,$L$2:$L$5001,0),"") | P9: =IF(O9="","",INDEX($A$2:$A$5001,O9)) | Q9: =IF(O9="","",INDEX($B$2:$B$5001,O9)) | R9: =IF(O9="","",INDEX($C$2:$C$5001,O9)) | S9: =IF(O9="","",INDEX($D$2:$D$5001,O9)) | T9: =IF(O9="","",INDEX($E$2:$E$5001,O9)) | V9: conflicts | W9: =SUM($K$2:$K$5001)
A10: =IF(screen_TA_reviewer_A!$A10="","",screen_TA_reviewer_A!$A10) | B10: =IF(OR($A10="",screen_TA_reviewer_A!$C10=""),"",screen_TA_reviewer_A!$C10) | C10: =IF(OR($A10="",screen_TA_reviewer_B!$C10=""),"",screen_TA_reviewer_B!$C10) | D10: =IF(OR($A10="",screen_TA_reviewer_A!$D10=""),"",screen_TA_reviewer_A!$D10) | E10: =IF(OR($A10="",screen_TA_reviewer_B!$D10=""),"",screen_TA_reviewer_B!$D10) | F10: =IF(AND(B10<>"",C10<>""),1,"") | G10: =IF(F10=1,IF(B10=C10,1,0),"") | H10: =IF(B10="","",IFERROR(VLOOKUP(B10,lst_TA_binary_map_table,2,FALSE),"INVALID")) | I10: =IF(C10="","",IFERROR(VLOOKUP(C10,lst_TA_binary_map_table,2,FALSE),"INVALID")) | J10: =IF(F10=1,IF(H10=I10,1,0),"") | K10: =IF(G10=0,1,"") | L10: =IF(K10=1,COUNTIF($K$2:K10,1),"") | N10: 9 | O10: =IFERROR(MATCH(N10,$L$2:$L$5001,0),"") | P10: =IF(O10="","",INDEX($A$2:$A$5001,O10)) | Q10: =IF(O10="","",INDEX($B$2:$B$5001,O10)) | R10: =IF(O10="","",INDEX($C$2:$C$5001,O10)) | S10: =IF(O10="","",INDEX($D$2:$D$5001,O10)) | T10: =IF(O10="","",INDEX($E$2:$E$5001,O10)) | V10: values outside the code list (INVALID) | W10: =COUNTIF($H$2:$H$5001,"INVALID")+COUNTIF($I$2:$I$5001,"INVALID")
A11: =IF(screen_TA_reviewer_A!$A11="","",screen_TA_reviewer_A!$A11) | B11: =IF(OR($A11="",screen_TA_reviewer_A!$C11=""),"",screen_TA_reviewer_A!$C11) | C11: =IF(OR($A11="",screen_TA_reviewer_B!$C11=""),"",screen_TA_reviewer_B!$C11) | D11: =IF(OR($A11="",screen_TA_reviewer_A!$D11=""),"",screen_TA_reviewer_A!$D11) | E11: =IF(OR($A11="",screen_TA_reviewer_B!$D11=""),"",screen_TA_reviewer_B!$D11) | F11: =IF(AND(B11<>"",C11<>""),1,"") | G11: =IF(F11=1,IF(B11=C11,1,0),"") | H11: =IF(B11="","",IFERROR(VLOOKUP(B11,lst_TA_binary_map_table,2,FALSE),"INVALID")) | I11: =IF(C11="","",IFERROR(VLOOKUP(C11,lst_TA_binary_map_table,2,FALSE),"INVALID")) | J11: =IF(F11=1,IF(H11=I11,1,0),"") | K11: =IF(G11=0,1,"") | L11: =IF(K11=1,COUNTIF($K$2:K11,1),"") | N11: 10 | O11: =IFERROR(MATCH(N11,$L$2:$L$5001,0),"") | P11: =IF(O11="","",INDEX($A$2:$A$5001,O11)) | Q11: =IF(O11="","",INDEX($B$2:$B$5001,O11)) | R11: =IF(O11="","",INDEX($C$2:$C$5001,O11)) | S11: =IF(O11="","",INDEX($D$2:$D$5001,O11)) | T11: =IF(O11="","",INDEX($E$2:$E$5001,O11)) | V11: capacity warning | W11: =IF(COUNTA(records_master!$A:$A)-1>5000,"MORE RECORDS THAN FORMULA ROWS (5000): regenerate with --rows",IF(W9>1000,"CONFLICTS EXCEED LIST (1000): filter column conflict",""))
A12: =IF(screen_TA_reviewer_A!$A12="","",screen_TA_reviewer_A!$A12) | B12: =IF(OR($A12="",screen_TA_reviewer_A!$C12=""),"",screen_TA_reviewer_A!$C12) | C12: =IF(OR($A12="",screen_TA_reviewer_B!$C12=""),"",screen_TA_reviewer_B!$C12) | D12: =IF(OR($A12="",screen_TA_reviewer_A!$D12=""),"",screen_TA_reviewer_A!$D12) | E12: =IF(OR($A12="",screen_TA_reviewer_B!$D12=""),"",screen_TA_reviewer_B!$D12) | F12: =IF(AND(B12<>"",C12<>""),1,"") | G12: =IF(F12=1,IF(B12=C12,1,0),"") | H12: =IF(B12="","",IFERROR(VLOOKUP(B12,lst_TA_binary_map_table,2,FALSE),"INVALID")) | I12: =IF(C12="","",IFERROR(VLOOKUP(C12,lst_TA_binary_map_table,2,FALSE),"INVALID")) | J12: =IF(F12=1,IF(H12=I12,1,0),"") | K12: =IF(G12=0,1,"") | L12: =IF(K12=1,COUNTIF($K$2:K12,1),"") | N12: 11 | O12: =IFERROR(MATCH(N12,$L$2:$L$5001,0),"") | P12: =IF(O12="","",INDEX($A$2:$A$5001,O12)) | Q12: =IF(O12="","",INDEX($B$2:$B$5001,O12)) | R12: =IF(O12="","",INDEX($C$2:$C$5001,O12)) | S12: =IF(O12="","",INDEX($D$2:$D$5001,O12)) | T12: =IF(O12="","",INDEX($E$2:$E$5001,O12))
A13: =IF(screen_TA_reviewer_A!$A13="","",screen_TA_reviewer_A!$A13) | B13: =IF(OR($A13="",screen_TA_reviewer_A!$C13=""),"",screen_TA_reviewer_A!$C13) | C13: =IF(OR($A13="",screen_TA_reviewer_B!$C13=""),"",screen_TA_reviewer_B!$C13) | D13: =IF(OR($A13="",screen_TA_reviewer_A!$D13=""),"",screen_TA_reviewer_A!$D13) | E13: =IF(OR($A13="",screen_TA_reviewer_B!$D13=""),"",screen_TA_reviewer_B!$D13) | F13: =IF(AND(B13<>"",C13<>""),1,"") | G13: =IF(F13=1,IF(B13=C13,1,0),"") | H13: =IF(B13="","",IFERROR(VLOOKUP(B13,lst_TA_binary_map_table,2,FALSE),"INVALID")) | I13: =IF(C13="","",IFERROR(VLOOKUP(C13,lst_TA_binary_map_table,2,FALSE),"INVALID")) | J13: =IF(F13=1,IF(H13=I13,1,0),"") | K13: =IF(G13=0,1,"") | L13: =IF(K13=1,COUNTIF($K$2:K13,1),"") | N13: 12 | O13: =IFERROR(MATCH(N13,$L$2:$L$5001,0),"") | P13: =IF(O13="","",INDEX($A$2:$A$5001,O13)) | Q13: =IF(O13="","",INDEX($B$2:$B$5001,O13)) | R13: =IF(O13="","",INDEX($C$2:$C$5001,O13)) | S13: =IF(O13="","",INDEX($D$2:$D$5001,O13)) | T13: =IF(O13="","",INDEX($E$2:$E$5001,O13)) | V13: Counts per reviewer (all decided records) | W13: reviewer A | X13: reviewer B
A14: =IF(screen_TA_reviewer_A!$A14="","",screen_TA_reviewer_A!$A14) | B14: =IF(OR($A14="",screen_TA_reviewer_A!$C14=""),"",screen_TA_reviewer_A!$C14) | C14: =IF(OR($A14="",screen_TA_reviewer_B!$C14=""),"",screen_TA_reviewer_B!$C14) | D14: =IF(OR($A14="",screen_TA_reviewer_A!$D14=""),"",screen_TA_reviewer_A!$D14) | E14: =IF(OR($A14="",screen_TA_reviewer_B!$D14=""),"",screen_TA_reviewer_B!$D14) | F14: =IF(AND(B14<>"",C14<>""),1,"") | G14: =IF(F14=1,IF(B14=C14,1,0),"") | H14: =IF(B14="","",IFERROR(VLOOKUP(B14,lst_TA_binary_map_table,2,FALSE),"INVALID")) | I14: =IF(C14="","",IFERROR(VLOOKUP(C14,lst_TA_binary_map_table,2,FALSE),"INVALID")) | J14: =IF(F14=1,IF(H14=I14,1,0),"") | K14: =IF(G14=0,1,"") | L14: =IF(K14=1,COUNTIF($K$2:K14,1),"") | N14: 13 | O14: =IFERROR(MATCH(N14,$L$2:$L$5001,0),"") | P14: =IF(O14="","",INDEX($A$2:$A$5001,O14)) | Q14: =IF(O14="","",INDEX($B$2:$B$5001,O14)) | R14: =IF(O14="","",INDEX($C$2:$C$5001,O14)) | S14: =IF(O14="","",INDEX($D$2:$D$5001,O14)) | T14: =IF(O14="","",INDEX($E$2:$E$5001,O14)) | V14: ADVANCE | W14: =COUNTIF($B$2:$B$5001,V14) | X14: =COUNTIF($C$2:$C$5001,V14)
A15: =IF(screen_TA_reviewer_A!$A15="","",screen_TA_reviewer_A!$A15) | B15: =IF(OR($A15="",screen_TA_reviewer_A!$C15=""),"",screen_TA_reviewer_A!$C15) | C15: =IF(OR($A15="",screen_TA_reviewer_B!$C15=""),"",screen_TA_reviewer_B!$C15) | D15: =IF(OR($A15="",screen_TA_reviewer_A!$D15=""),"",screen_TA_reviewer_A!$D15) | E15: =IF(OR($A15="",screen_TA_reviewer_B!$D15=""),"",screen_TA_reviewer_B!$D15) | F15: =IF(AND(B15<>"",C15<>""),1,"") | G15: =IF(F15=1,IF(B15=C15,1,0),"") | H15: =IF(B15="","",IFERROR(VLOOKUP(B15,lst_TA_binary_map_table,2,FALSE),"INVALID")) | I15: =IF(C15="","",IFERROR(VLOOKUP(C15,lst_TA_binary_map_table,2,FALSE),"INVALID")) | J15: =IF(F15=1,IF(H15=I15,1,0),"") | K15: =IF(G15=0,1,"") | L15: =IF(K15=1,COUNTIF($K$2:K15,1),"") | N15: 14 | O15: =IFERROR(MATCH(N15,$L$2:$L$5001,0),"") | P15: =IF(O15="","",INDEX($A$2:$A$5001,O15)) | Q15: =IF(O15="","",INDEX($B$2:$B$5001,O15)) | R15: =IF(O15="","",INDEX($C$2:$C$5001,O15)) | S15: =IF(O15="","",INDEX($D$2:$D$5001,O15)) | T15: =IF(O15="","",INDEX($E$2:$E$5001,O15)) | V15: EXCLUDE_TA | W15: =COUNTIF($B$2:$B$5001,V15) | X15: =COUNTIF($C$2:$C$5001,V15)
A16: =IF(screen_TA_reviewer_A!$A16="","",screen_TA_reviewer_A!$A16) | B16: =IF(OR($A16="",screen_TA_reviewer_A!$C16=""),"",screen_TA_reviewer_A!$C16) | C16: =IF(OR($A16="",screen_TA_reviewer_B!$C16=""),"",screen_TA_reviewer_B!$C16) | D16: =IF(OR($A16="",screen_TA_reviewer_A!$D16=""),"",screen_TA_reviewer_A!$D16) | E16: =IF(OR($A16="",screen_TA_reviewer_B!$D16=""),"",screen_TA_reviewer_B!$D16) | F16: =IF(AND(B16<>"",C16<>""),1,"") | G16: =IF(F16=1,IF(B16=C16,1,0),"") | H16: =IF(B16="","",IFERROR(VLOOKUP(B16,lst_TA_binary_map_table,2,FALSE),"INVALID")) | I16: =IF(C16="","",IFERROR(VLOOKUP(C16,lst_TA_binary_map_table,2,FALSE),"INVALID")) | J16: =IF(F16=1,IF(H16=I16,1,0),"") | K16: =IF(G16=0,1,"") | L16: =IF(K16=1,COUNTIF($K$2:K16,1),"") | N16: 15 | O16: =IFERROR(MATCH(N16,$L$2:$L$5001,0),"") | P16: =IF(O16="","",INDEX($A$2:$A$5001,O16)) | Q16: =IF(O16="","",INDEX($B$2:$B$5001,O16)) | R16: =IF(O16="","",INDEX($C$2:$C$5001,O16)) | S16: =IF(O16="","",INDEX($D$2:$D$5001,O16)) | T16: =IF(O16="","",INDEX($E$2:$E$5001,O16)) | V16: FRONTIER_PREPRINT | W16: =COUNTIF($B$2:$B$5001,V16) | X16: =COUNTIF($C$2:$C$5001,V16)
A17: =IF(screen_TA_reviewer_A!$A17="","",screen_TA_reviewer_A!$A17) | B17: =IF(OR($A17="",screen_TA_reviewer_A!$C17=""),"",screen_TA_reviewer_A!$C17) | C17: =IF(OR($A17="",screen_TA_reviewer_B!$C17=""),"",screen_TA_reviewer_B!$C17) | D17: =IF(OR($A17="",screen_TA_reviewer_A!$D17=""),"",screen_TA_reviewer_A!$D17) | E17: =IF(OR($A17="",screen_TA_reviewer_B!$D17=""),"",screen_TA_reviewer_B!$D17) | F17: =IF(AND(B17<>"",C17<>""),1,"") | G17: =IF(F17=1,IF(B17=C17,1,0),"") | H17: =IF(B17="","",IFERROR(VLOOKUP(B17,lst_TA_binary_map_table,2,FALSE),"INVALID")) | I17: =IF(C17="","",IFERROR(VLOOKUP(C17,lst_TA_binary_map_table,2,FALSE),"INVALID")) | J17: =IF(F17=1,IF(H17=I17,1,0),"") | K17: =IF(G17=0,1,"") | L17: =IF(K17=1,COUNTIF($K$2:K17,1),"") | N17: 16 | O17: =IFERROR(MATCH(N17,$L$2:$L$5001,0),"") | P17: =IF(O17="","",INDEX($A$2:$A$5001,O17)) | Q17: =IF(O17="","",INDEX($B$2:$B$5001,O17)) | R17: =IF(O17="","",INDEX($C$2:$C$5001,O17)) | S17: =IF(O17="","",INDEX($D$2:$D$5001,O17)) | T17: =IF(O17="","",INDEX($E$2:$E$5001,O17)) | V17: AWAITING_CLASSIFICATION | W17: =COUNTIF($B$2:$B$5001,V17) | X17: =COUNTIF($C$2:$C$5001,V17)
A18: =IF(screen_TA_reviewer_A!$A18="","",screen_TA_reviewer_A!$A18) | B18: =IF(OR($A18="",screen_TA_reviewer_A!$C18=""),"",screen_TA_reviewer_A!$C18) | C18: =IF(OR($A18="",screen_TA_reviewer_B!$C18=""),"",screen_TA_reviewer_B!$C18) | D18: =IF(OR($A18="",screen_TA_reviewer_A!$D18=""),"",screen_TA_reviewer_A!$D18) | E18: =IF(OR($A18="",screen_TA_reviewer_B!$D18=""),"",screen_TA_reviewer_B!$D18) | F18: =IF(AND(B18<>"",C18<>""),1,"") | G18: =IF(F18=1,IF(B18=C18,1,0),"") | H18: =IF(B18="","",IFERROR(VLOOKUP(B18,lst_TA_binary_map_table,2,FALSE),"INVALID")) | I18: =IF(C18="","",IFERROR(VLOOKUP(C18,lst_TA_binary_map_table,2,FALSE),"INVALID")) | J18: =IF(F18=1,IF(H18=I18,1,0),"") | K18: =IF(G18=0,1,"") | L18: =IF(K18=1,COUNTIF($K$2:K18,1),"") | N18: 17 | O18: =IFERROR(MATCH(N18,$L$2:$L$5001,0),"") | P18: =IF(O18="","",INDEX($A$2:$A$5001,O18)) | Q18: =IF(O18="","",INDEX($B$2:$B$5001,O18)) | R18: =IF(O18="","",INDEX($C$2:$C$5001,O18)) | S18: =IF(O18="","",INDEX($D$2:$D$5001,O18)) | T18: =IF(O18="","",INDEX($E$2:$E$5001,O18))
A19: =IF(screen_TA_reviewer_A!$A19="","",screen_TA_reviewer_A!$A19) | B19: =IF(OR($A19="",screen_TA_reviewer_A!$C19=""),"",screen_TA_reviewer_A!$C19) | C19: =IF(OR($A19="",screen_TA_reviewer_B!$C19=""),"",screen_TA_reviewer_B!$C19) | D19: =IF(OR($A19="",screen_TA_reviewer_A!$D19=""),"",screen_TA_reviewer_A!$D19) | E19: =IF(OR($A19="",screen_TA_reviewer_B!$D19=""),"",screen_TA_reviewer_B!$D19) | F19: =IF(AND(B19<>"",C19<>""),1,"") | G19: =IF(F19=1,IF(B19=C19,1,0),"") | H19: =IF(B19="","",IFERROR(VLOOKUP(B19,lst_TA_binary_map_table,2,FALSE),"INVALID")) | I19: =IF(C19="","",IFERROR(VLOOKUP(C19,lst_TA_binary_map_table,2,FALSE),"INVALID")) | J19: =IF(F19=1,IF(H19=I19,1,0),"") | K19: =IF(G19=0,1,"") | L19: =IF(K19=1,COUNTIF($K$2:K19,1),"") | N19: 18 | O19: =IFERROR(MATCH(N19,$L$2:$L$5001,0),"") | P19: =IF(O19="","",INDEX($A$2:$A$5001,O19)) | Q19: =IF(O19="","",INDEX($B$2:$B$5001,O19)) | R19: =IF(O19="","",INDEX($C$2:$C$5001,O19)) | S19: =IF(O19="","",INDEX($D$2:$D$5001,O19)) | T19: =IF(O19="","",INDEX($E$2:$E$5001,O19)) | V19: Agreement on exact TA disposition (4×4)
A20: =IF(screen_TA_reviewer_A!$A20="","",screen_TA_reviewer_A!$A20) | B20: =IF(OR($A20="",screen_TA_reviewer_A!$C20=""),"",screen_TA_reviewer_A!$C20) | C20: =IF(OR($A20="",screen_TA_reviewer_B!$C20=""),"",screen_TA_reviewer_B!$C20) | D20: =IF(OR($A20="",screen_TA_reviewer_A!$D20=""),"",screen_TA_reviewer_A!$D20) | E20: =IF(OR($A20="",screen_TA_reviewer_B!$D20=""),"",screen_TA_reviewer_B!$D20) | F20: =IF(AND(B20<>"",C20<>""),1,"") | G20: =IF(F20=1,IF(B20=C20,1,0),"") | H20: =IF(B20="","",IFERROR(VLOOKUP(B20,lst_TA_binary_map_table,2,FALSE),"INVALID")) | I20: =IF(C20="","",IFERROR(VLOOKUP(C20,lst_TA_binary_map_table,2,FALSE),"INVALID")) | J20: =IF(F20=1,IF(H20=I20,1,0),"") | K20: =IF(G20=0,1,"") | L20: =IF(K20=1,COUNTIF($K$2:K20,1),"") | N20: 19 | O20: =IFERROR(MATCH(N20,$L$2:$L$5001,0),"") | P20: =IF(O20="","",INDEX($A$2:$A$5001,O20)) | Q20: =IF(O20="","",INDEX($B$2:$B$5001,O20)) | R20: =IF(O20="","",INDEX($C$2:$C$5001,O20)) | S20: =IF(O20="","",INDEX($D$2:$D$5001,O20)) | T20: =IF(O20="","",INDEX($E$2:$E$5001,O20)) | V20: A (rows) \ B (cols) | W20: ADVANCE | X20: EXCLUDE_TA | Y20: FRONTIER_PREPRINT | Z20: AWAITING_CLASSIFICATION | AA20: row total (A)
A21: =IF(screen_TA_reviewer_A!$A21="","",screen_TA_reviewer_A!$A21) | B21: =IF(OR($A21="",screen_TA_reviewer_A!$C21=""),"",screen_TA_reviewer_A!$C21) | C21: =IF(OR($A21="",screen_TA_reviewer_B!$C21=""),"",screen_TA_reviewer_B!$C21) | D21: =IF(OR($A21="",screen_TA_reviewer_A!$D21=""),"",screen_TA_reviewer_A!$D21) | E21: =IF(OR($A21="",screen_TA_reviewer_B!$D21=""),"",screen_TA_reviewer_B!$D21) | F21: =IF(AND(B21<>"",C21<>""),1,"") | G21: =IF(F21=1,IF(B21=C21,1,0),"") | H21: =IF(B21="","",IFERROR(VLOOKUP(B21,lst_TA_binary_map_table,2,FALSE),"INVALID")) | I21: =IF(C21="","",IFERROR(VLOOKUP(C21,lst_TA_binary_map_table,2,FALSE),"INVALID")) | J21: =IF(F21=1,IF(H21=I21,1,0),"") | K21: =IF(G21=0,1,"") | L21: =IF(K21=1,COUNTIF($K$2:K21,1),"") | N21: 20 | O21: =IFERROR(MATCH(N21,$L$2:$L$5001,0),"") | P21: =IF(O21="","",INDEX($A$2:$A$5001,O21)) | Q21: =IF(O21="","",INDEX($B$2:$B$5001,O21)) | R21: =IF(O21="","",INDEX($C$2:$C$5001,O21)) | S21: =IF(O21="","",INDEX($D$2:$D$5001,O21)) | T21: =IF(O21="","",INDEX($E$2:$E$5001,O21)) | V21: ADVANCE | W21: =COUNTIFS($B$2:$B$5001,$V21,$C$2:$C$5001,W$20) | X21: =COUNTIFS($B$2:$B$5001,$V21,$C$2:$C$5001,X$20) | Y21: =COUNTIFS($B$2:$B$5001,$V21,$C$2:$C$5001,Y$20) | Z21: =COUNTIFS($B$2:$B$5001,$V21,$C$2:$C$5001,Z$20) | AA21: =SUM(W21:Z21)
A22: =IF(screen_TA_reviewer_A!$A22="","",screen_TA_reviewer_A!$A22) | B22: =IF(OR($A22="",screen_TA_reviewer_A!$C22=""),"",screen_TA_reviewer_A!$C22) | C22: =IF(OR($A22="",screen_TA_reviewer_B!$C22=""),"",screen_TA_reviewer_B!$C22) | D22: =IF(OR($A22="",screen_TA_reviewer_A!$D22=""),"",screen_TA_reviewer_A!$D22) | E22: =IF(OR($A22="",screen_TA_reviewer_B!$D22=""),"",screen_TA_reviewer_B!$D22) | F22: =IF(AND(B22<>"",C22<>""),1,"") | G22: =IF(F22=1,IF(B22=C22,1,0),"") | H22: =IF(B22="","",IFERROR(VLOOKUP(B22,lst_TA_binary_map_table,2,FALSE),"INVALID")) | I22: =IF(C22="","",IFERROR(VLOOKUP(C22,lst_TA_binary_map_table,2,FALSE),"INVALID")) | J22: =IF(F22=1,IF(H22=I22,1,0),"") | K22: =IF(G22=0,1,"") | L22: =IF(K22=1,COUNTIF($K$2:K22,1),"") | N22: 21 | O22: =IFERROR(MATCH(N22,$L$2:$L$5001,0),"") | P22: =IF(O22="","",INDEX($A$2:$A$5001,O22)) | Q22: =IF(O22="","",INDEX($B$2:$B$5001,O22)) | R22: =IF(O22="","",INDEX($C$2:$C$5001,O22)) | S22: =IF(O22="","",INDEX($D$2:$D$5001,O22)) | T22: =IF(O22="","",INDEX($E$2:$E$5001,O22)) | V22: EXCLUDE_TA | W22: =COUNTIFS($B$2:$B$5001,$V22,$C$2:$C$5001,W$20) | X22: =COUNTIFS($B$2:$B$5001,$V22,$C$2:$C$5001,X$20) | Y22: =COUNTIFS($B$2:$B$5001,$V22,$C$2:$C$5001,Y$20) | Z22: =COUNTIFS($B$2:$B$5001,$V22,$C$2:$C$5001,Z$20) | AA22: =SUM(W22:Z22)
A23: =IF(screen_TA_reviewer_A!$A23="","",screen_TA_reviewer_A!$A23) | B23: =IF(OR($A23="",screen_TA_reviewer_A!$C23=""),"",screen_TA_reviewer_A!$C23) | C23: =IF(OR($A23="",screen_TA_reviewer_B!$C23=""),"",screen_TA_reviewer_B!$C23) | D23: =IF(OR($A23="",screen_TA_reviewer_A!$D23=""),"",screen_TA_reviewer_A!$D23) | E23: =IF(OR($A23="",screen_TA_reviewer_B!$D23=""),"",screen_TA_reviewer_B!$D23) | F23: =IF(AND(B23<>"",C23<>""),1,"") | G23: =IF(F23=1,IF(B23=C23,1,0),"") | H23: =IF(B23="","",IFERROR(VLOOKUP(B23,lst_TA_binary_map_table,2,FALSE),"INVALID")) | I23: =IF(C23="","",IFERROR(VLOOKUP(C23,lst_TA_binary_map_table,2,FALSE),"INVALID")) | J23: =IF(F23=1,IF(H23=I23,1,0),"") | K23: =IF(G23=0,1,"") | L23: =IF(K23=1,COUNTIF($K$2:K23,1),"") | N23: 22 | O23: =IFERROR(MATCH(N23,$L$2:$L$5001,0),"") | P23: =IF(O23="","",INDEX($A$2:$A$5001,O23)) | Q23: =IF(O23="","",INDEX($B$2:$B$5001,O23)) | R23: =IF(O23="","",INDEX($C$2:$C$5001,O23)) | S23: =IF(O23="","",INDEX($D$2:$D$5001,O23)) | T23: =IF(O23="","",INDEX($E$2:$E$5001,O23)) | V23: FRONTIER_PREPRINT | W23: =COUNTIFS($B$2:$B$5001,$V23,$C$2:$C$5001,W$20) | X23: =COUNTIFS($B$2:$B$5001,$V23,$C$2:$C$5001,X$20) | Y23: =COUNTIFS($B$2:$B$5001,$V23,$C$2:$C$5001,Y$20) | Z23: =COUNTIFS($B$2:$B$5001,$V23,$C$2:$C$5001,Z$20) | AA23: =SUM(W23:Z23)
A24: =IF(screen_TA_reviewer_A!$A24="","",screen_TA_reviewer_A!$A24) | B24: =IF(OR($A24="",screen_TA_reviewer_A!$C24=""),"",screen_TA_reviewer_A!$C24) | C24: =IF(OR($A24="",screen_TA_reviewer_B!$C24=""),"",screen_TA_reviewer_B!$C24) | D24: =IF(OR($A24="",screen_TA_reviewer_A!$D24=""),"",screen_TA_reviewer_A!$D24) | E24: =IF(OR($A24="",screen_TA_reviewer_B!$D24=""),"",screen_TA_reviewer_B!$D24) | F24: =IF(AND(B24<>"",C24<>""),1,"") | G24: =IF(F24=1,IF(B24=C24,1,0),"") | H24: =IF(B24="","",IFERROR(VLOOKUP(B24,lst_TA_binary_map_table,2,FALSE),"INVALID")) | I24: =IF(C24="","",IFERROR(VLOOKUP(C24,lst_TA_binary_map_table,2,FALSE),"INVALID")) | J24: =IF(F24=1,IF(H24=I24,1,0),"") | K24: =IF(G24=0,1,"") | L24: =IF(K24=1,COUNTIF($K$2:K24,1),"") | N24: 23 | O24: =IFERROR(MATCH(N24,$L$2:$L$5001,0),"") | P24: =IF(O24="","",INDEX($A$2:$A$5001,O24)) | Q24: =IF(O24="","",INDEX($B$2:$B$5001,O24)) | R24: =IF(O24="","",INDEX($C$2:$C$5001,O24)) | S24: =IF(O24="","",INDEX($D$2:$D$5001,O24)) | T24: =IF(O24="","",INDEX($E$2:$E$5001,O24)) | V24: AWAITING_CLASSIFICATION | W24: =COUNTIFS($B$2:$B$5001,$V24,$C$2:$C$5001,W$20) | X24: =COUNTIFS($B$2:$B$5001,$V24,$C$2:$C$5001,X$20) | Y24: =COUNTIFS($B$2:$B$5001,$V24,$C$2:$C$5001,Y$20) | Z24: =COUNTIFS($B$2:$B$5001,$V24,$C$2:$C$5001,Z$20) | AA24: =SUM(W24:Z24)
A25: =IF(screen_TA_reviewer_A!$A25="","",screen_TA_reviewer_A!$A25) | B25: =IF(OR($A25="",screen_TA_reviewer_A!$C25=""),"",screen_TA_reviewer_A!$C25) | C25: =IF(OR($A25="",screen_TA_reviewer_B!$C25=""),"",screen_TA_reviewer_B!$C25) | D25: =IF(OR($A25="",screen_TA_reviewer_A!$D25=""),"",screen_TA_reviewer_A!$D25) | E25: =IF(OR($A25="",screen_TA_reviewer_B!$D25=""),"",screen_TA_reviewer_B!$D25) | F25: =IF(AND(B25<>"",C25<>""),1,"") | G25: =IF(F25=1,IF(B25=C25,1,0),"") | H25: =IF(B25="","",IFERROR(VLOOKUP(B25,lst_TA_binary_map_table,2,FALSE),"INVALID")) | I25: =IF(C25="","",IFERROR(VLOOKUP(C25,lst_TA_binary_map_table,2,FALSE),"INVALID")) | J25: =IF(F25=1,IF(H25=I25,1,0),"") | K25: =IF(G25=0,1,"") | L25: =IF(K25=1,COUNTIF($K$2:K25,1),"") | N25: 24 | O25: =IFERROR(MATCH(N25,$L$2:$L$5001,0),"") | P25: =IF(O25="","",INDEX($A$2:$A$5001,O25)) | Q25: =IF(O25="","",INDEX($B$2:$B$5001,O25)) | R25: =IF(O25="","",INDEX($C$2:$C$5001,O25)) | S25: =IF(O25="","",INDEX($D$2:$D$5001,O25)) | T25: =IF(O25="","",INDEX($E$2:$E$5001,O25)) | V25: column total (B) | W25: =SUM(W21:W24) | X25: =SUM(X21:X24) | Y25: =SUM(Y21:Y24) | Z25: =SUM(Z21:Z24) | AA25: =SUM(AA21:AA24)
A26: =IF(screen_TA_reviewer_A!$A26="","",screen_TA_reviewer_A!$A26) | B26: =IF(OR($A26="",screen_TA_reviewer_A!$C26=""),"",screen_TA_reviewer_A!$C26) | C26: =IF(OR($A26="",screen_TA_reviewer_B!$C26=""),"",screen_TA_reviewer_B!$C26) | D26: =IF(OR($A26="",screen_TA_reviewer_A!$D26=""),"",screen_TA_reviewer_A!$D26) | E26: =IF(OR($A26="",screen_TA_reviewer_B!$D26=""),"",screen_TA_reviewer_B!$D26) | F26: =IF(AND(B26<>"",C26<>""),1,"") | G26: =IF(F26=1,IF(B26=C26,1,0),"") | H26: =IF(B26="","",IFERROR(VLOOKUP(B26,lst_TA_binary_map_table,2,FALSE),"INVALID")) | I26: =IF(C26="","",IFERROR(VLOOKUP(C26,lst_TA_binary_map_table,2,FALSE),"INVALID")) | J26: =IF(F26=1,IF(H26=I26,1,0),"") | K26: =IF(G26=0,1,"") | L26: =IF(K26=1,COUNTIF($K$2:K26,1),"") | N26: 25 | O26: =IFERROR(MATCH(N26,$L$2:$L$5001,0),"") | P26: =IF(O26="","",INDEX($A$2:$A$5001,O26)) | Q26: =IF(O26="","",INDEX($B$2:$B$5001,O26)) | R26: =IF(O26="","",INDEX($C$2:$C$5001,O26)) | S26: =IF(O26="","",INDEX($D$2:$D$5001,O26)) | T26: =IF(O26="","",INDEX($E$2:$E$5001,O26)) | V26: n (jointly coded with listed codes) | W26: =AA25
A27: =IF(screen_TA_reviewer_A!$A27="","",screen_TA_reviewer_A!$A27) | B27: =IF(OR($A27="",screen_TA_reviewer_A!$C27=""),"",screen_TA_reviewer_A!$C27) | C27: =IF(OR($A27="",screen_TA_reviewer_B!$C27=""),"",screen_TA_reviewer_B!$C27) | D27: =IF(OR($A27="",screen_TA_reviewer_A!$D27=""),"",screen_TA_reviewer_A!$D27) | E27: =IF(OR($A27="",screen_TA_reviewer_B!$D27=""),"",screen_TA_reviewer_B!$D27) | F27: =IF(AND(B27<>"",C27<>""),1,"") | G27: =IF(F27=1,IF(B27=C27,1,0),"") | H27: =IF(B27="","",IFERROR(VLOOKUP(B27,lst_TA_binary_map_table,2,FALSE),"INVALID")) | I27: =IF(C27="","",IFERROR(VLOOKUP(C27,lst_TA_binary_map_table,2,FALSE),"INVALID")) | J27: =IF(F27=1,IF(H27=I27,1,0),"") | K27: =IF(G27=0,1,"") | L27: =IF(K27=1,COUNTIF($K$2:K27,1),"") | N27: 26 | O27: =IFERROR(MATCH(N27,$L$2:$L$5001,0),"") | P27: =IF(O27="","",INDEX($A$2:$A$5001,O27)) | Q27: =IF(O27="","",INDEX($B$2:$B$5001,O27)) | R27: =IF(O27="","",INDEX($C$2:$C$5001,O27)) | S27: =IF(O27="","",INDEX($D$2:$D$5001,O27)) | T27: =IF(O27="","",INDEX($E$2:$E$5001,O27)) | V27: observed agreements (diagonal) | W27: =SUM(W21,X22,Y23,Z24)
A28: =IF(screen_TA_reviewer_A!$A28="","",screen_TA_reviewer_A!$A28) | B28: =IF(OR($A28="",screen_TA_reviewer_A!$C28=""),"",screen_TA_reviewer_A!$C28) | C28: =IF(OR($A28="",screen_TA_reviewer_B!$C28=""),"",screen_TA_reviewer_B!$C28) | D28: =IF(OR($A28="",screen_TA_reviewer_A!$D28=""),"",screen_TA_reviewer_A!$D28) | E28: =IF(OR($A28="",screen_TA_reviewer_B!$D28=""),"",screen_TA_reviewer_B!$D28) | F28: =IF(AND(B28<>"",C28<>""),1,"") | G28: =IF(F28=1,IF(B28=C28,1,0),"") | H28: =IF(B28="","",IFERROR(VLOOKUP(B28,lst_TA_binary_map_table,2,FALSE),"INVALID")) | I28: =IF(C28="","",IFERROR(VLOOKUP(C28,lst_TA_binary_map_table,2,FALSE),"INVALID")) | J28: =IF(F28=1,IF(H28=I28,1,0),"") | K28: =IF(G28=0,1,"") | L28: =IF(K28=1,COUNTIF($K$2:K28,1),"") | N28: 27 | O28: =IFERROR(MATCH(N28,$L$2:$L$5001,0),"") | P28: =IF(O28="","",INDEX($A$2:$A$5001,O28)) | Q28: =IF(O28="","",INDEX($B$2:$B$5001,O28)) | R28: =IF(O28="","",INDEX($C$2:$C$5001,O28)) | S28: =IF(O28="","",INDEX($D$2:$D$5001,O28)) | T28: =IF(O28="","",INDEX($E$2:$E$5001,O28)) | V28: raw agreement p_o | W28: =IF(W26=0,"",W27/W26)
A29: =IF(screen_TA_reviewer_A!$A29="","",screen_TA_reviewer_A!$A29) | B29: =IF(OR($A29="",screen_TA_reviewer_A!$C29=""),"",screen_TA_reviewer_A!$C29) | C29: =IF(OR($A29="",screen_TA_reviewer_B!$C29=""),"",screen_TA_reviewer_B!$C29) | D29: =IF(OR($A29="",screen_TA_reviewer_A!$D29=""),"",screen_TA_reviewer_A!$D29) | E29: =IF(OR($A29="",screen_TA_reviewer_B!$D29=""),"",screen_TA_reviewer_B!$D29) | F29: =IF(AND(B29<>"",C29<>""),1,"") | G29: =IF(F29=1,IF(B29=C29,1,0),"") | H29: =IF(B29="","",IFERROR(VLOOKUP(B29,lst_TA_binary_map_table,2,FALSE),"INVALID")) | I29: =IF(C29="","",IFERROR(VLOOKUP(C29,lst_TA_binary_map_table,2,FALSE),"INVALID")) | J29: =IF(F29=1,IF(H29=I29,1,0),"") | K29: =IF(G29=0,1,"") | L29: =IF(K29=1,COUNTIF($K$2:K29,1),"") | N29: 28 | O29: =IFERROR(MATCH(N29,$L$2:$L$5001,0),"") | P29: =IF(O29="","",INDEX($A$2:$A$5001,O29)) | Q29: =IF(O29="","",INDEX($B$2:$B$5001,O29)) | R29: =IF(O29="","",INDEX($C$2:$C$5001,O29)) | S29: =IF(O29="","",INDEX($D$2:$D$5001,O29)) | T29: =IF(O29="","",INDEX($E$2:$E$5001,O29)) | V29: chance agreement p_e | W29: =IF(W26=0,"",(AA21*W25+AA22*X25+AA23*Y25+AA24*Z25)/W26^2)
A30: =IF(screen_TA_reviewer_A!$A30="","",screen_TA_reviewer_A!$A30) | B30: =IF(OR($A30="",screen_TA_reviewer_A!$C30=""),"",screen_TA_reviewer_A!$C30) | C30: =IF(OR($A30="",screen_TA_reviewer_B!$C30=""),"",screen_TA_reviewer_B!$C30) | D30: =IF(OR($A30="",screen_TA_reviewer_A!$D30=""),"",screen_TA_reviewer_A!$D30) | E30: =IF(OR($A30="",screen_TA_reviewer_B!$D30=""),"",screen_TA_reviewer_B!$D30) | F30: =IF(AND(B30<>"",C30<>""),1,"") | G30: =IF(F30=1,IF(B30=C30,1,0),"") | H30: =IF(B30="","",IFERROR(VLOOKUP(B30,lst_TA_binary_map_table,2,FALSE),"INVALID")) | I30: =IF(C30="","",IFERROR(VLOOKUP(C30,lst_TA_binary_map_table,2,FALSE),"INVALID")) | J30: =IF(F30=1,IF(H30=I30,1,0),"") | K30: =IF(G30=0,1,"") | L30: =IF(K30=1,COUNTIF($K$2:K30,1),"") | N30: 29 | O30: =IFERROR(MATCH(N30,$L$2:$L$5001,0),"") | P30: =IF(O30="","",INDEX($A$2:$A$5001,O30)) | Q30: =IF(O30="","",INDEX($B$2:$B$5001,O30)) | R30: =IF(O30="","",INDEX($C$2:$C$5001,O30)) | S30: =IF(O30="","",INDEX($D$2:$D$5001,O30)) | T30: =IF(O30="","",INDEX($E$2:$E$5001,O30)) | V30: Cohen's kappa (descriptive) | W30: =IF(W26=0,"",IF(W29=1,"undefined (p_e=1)",(W28-W29)/(1-W29)))
A31: =IF(screen_TA_reviewer_A!$A31="","",screen_TA_reviewer_A!$A31) | B31: =IF(OR($A31="",screen_TA_reviewer_A!$C31=""),"",screen_TA_reviewer_A!$C31) | C31: =IF(OR($A31="",screen_TA_reviewer_B!$C31=""),"",screen_TA_reviewer_B!$C31) | D31: =IF(OR($A31="",screen_TA_reviewer_A!$D31=""),"",screen_TA_reviewer_A!$D31) | E31: =IF(OR($A31="",screen_TA_reviewer_B!$D31=""),"",screen_TA_reviewer_B!$D31) | F31: =IF(AND(B31<>"",C31<>""),1,"") | G31: =IF(F31=1,IF(B31=C31,1,0),"") | H31: =IF(B31="","",IFERROR(VLOOKUP(B31,lst_TA_binary_map_table,2,FALSE),"INVALID")) | I31: =IF(C31="","",IFERROR(VLOOKUP(C31,lst_TA_binary_map_table,2,FALSE),"INVALID")) | J31: =IF(F31=1,IF(H31=I31,1,0),"") | K31: =IF(G31=0,1,"") | L31: =IF(K31=1,COUNTIF($K$2:K31,1),"") | N31: 30 | O31: =IFERROR(MATCH(N31,$L$2:$L$5001,0),"") | P31: =IF(O31="","",INDEX($A$2:$A$5001,O31)) | Q31: =IF(O31="","",INDEX($B$2:$B$5001,O31)) | R31: =IF(O31="","",INDEX($C$2:$C$5001,O31)) | S31: =IF(O31="","",INDEX($D$2:$D$5001,O31)) | T31: =IF(O31="","",INDEX($E$2:$E$5001,O31))
A32: =IF(screen_TA_reviewer_A!$A32="","",screen_TA_reviewer_A!$A32) | B32: =IF(OR($A32="",screen_TA_reviewer_A!$C32=""),"",screen_TA_reviewer_A!$C32) | C32: =IF(OR($A32="",screen_TA_reviewer_B!$C32=""),"",screen_TA_reviewer_B!$C32) | D32: =IF(OR($A32="",screen_TA_reviewer_A!$D32=""),"",screen_TA_reviewer_A!$D32) | E32: =IF(OR($A32="",screen_TA_reviewer_B!$D32=""),"",screen_TA_reviewer_B!$D32) | F32: =IF(AND(B32<>"",C32<>""),1,"") | G32: =IF(F32=1,IF(B32=C32,1,0),"") | H32: =IF(B32="","",IFERROR(VLOOKUP(B32,lst_TA_binary_map_table,2,FALSE),"INVALID")) | I32: =IF(C32="","",IFERROR(VLOOKUP(C32,lst_TA_binary_map_table,2,FALSE),"INVALID")) | J32: =IF(F32=1,IF(H32=I32,1,0),"") | K32: =IF(G32=0,1,"") | L32: =IF(K32=1,COUNTIF($K$2:K32,1),"") | N32: 31 | O32: =IFERROR(MATCH(N32,$L$2:$L$5001,0),"") | P32: =IF(O32="","",INDEX($A$2:$A$5001,O32)) | Q32: =IF(O32="","",INDEX($B$2:$B$5001,O32)) | R32: =IF(O32="","",INDEX($C$2:$C$5001,O32)) | S32: =IF(O32="","",INDEX($D$2:$D$5001,O32)) | T32: =IF(O32="","",INDEX($E$2:$E$5001,O32)) | V32: Agreement on calibration binary disposition (2×2)
A33: =IF(screen_TA_reviewer_A!$A33="","",screen_TA_reviewer_A!$A33) | B33: =IF(OR($A33="",screen_TA_reviewer_A!$C33=""),"",screen_TA_reviewer_A!$C33) | C33: =IF(OR($A33="",screen_TA_reviewer_B!$C33=""),"",screen_TA_reviewer_B!$C33) | D33: =IF(OR($A33="",screen_TA_reviewer_A!$D33=""),"",screen_TA_reviewer_A!$D33) | E33: =IF(OR($A33="",screen_TA_reviewer_B!$D33=""),"",screen_TA_reviewer_B!$D33) | F33: =IF(AND(B33<>"",C33<>""),1,"") | G33: =IF(F33=1,IF(B33=C33,1,0),"") | H33: =IF(B33="","",IFERROR(VLOOKUP(B33,lst_TA_binary_map_table,2,FALSE),"INVALID")) | I33: =IF(C33="","",IFERROR(VLOOKUP(C33,lst_TA_binary_map_table,2,FALSE),"INVALID")) | J33: =IF(F33=1,IF(H33=I33,1,0),"") | K33: =IF(G33=0,1,"") | L33: =IF(K33=1,COUNTIF($K$2:K33,1),"") | N33: 32 | O33: =IFERROR(MATCH(N33,$L$2:$L$5001,0),"") | P33: =IF(O33="","",INDEX($A$2:$A$5001,O33)) | Q33: =IF(O33="","",INDEX($B$2:$B$5001,O33)) | R33: =IF(O33="","",INDEX($C$2:$C$5001,O33)) | S33: =IF(O33="","",INDEX($D$2:$D$5001,O33)) | T33: =IF(O33="","",INDEX($E$2:$E$5001,O33)) | V33: A (rows) \ B (cols) | W33: progress / do not exclude | X33: EXCLUDE_TA | Y33: row total (A)
A34: =IF(screen_TA_reviewer_A!$A34="","",screen_TA_reviewer_A!$A34) | B34: =IF(OR($A34="",screen_TA_reviewer_A!$C34=""),"",screen_TA_reviewer_A!$C34) | C34: =IF(OR($A34="",screen_TA_reviewer_B!$C34=""),"",screen_TA_reviewer_B!$C34) | D34: =IF(OR($A34="",screen_TA_reviewer_A!$D34=""),"",screen_TA_reviewer_A!$D34) | E34: =IF(OR($A34="",screen_TA_reviewer_B!$D34=""),"",screen_TA_reviewer_B!$D34) | F34: =IF(AND(B34<>"",C34<>""),1,"") | G34: =IF(F34=1,IF(B34=C34,1,0),"") | H34: =IF(B34="","",IFERROR(VLOOKUP(B34,lst_TA_binary_map_table,2,FALSE),"INVALID")) | I34: =IF(C34="","",IFERROR(VLOOKUP(C34,lst_TA_binary_map_table,2,FALSE),"INVALID")) | J34: =IF(F34=1,IF(H34=I34,1,0),"") | K34: =IF(G34=0,1,"") | L34: =IF(K34=1,COUNTIF($K$2:K34,1),"") | N34: 33 | O34: =IFERROR(MATCH(N34,$L$2:$L$5001,0),"") | P34: =IF(O34="","",INDEX($A$2:$A$5001,O34)) | Q34: =IF(O34="","",INDEX($B$2:$B$5001,O34)) | R34: =IF(O34="","",INDEX($C$2:$C$5001,O34)) | S34: =IF(O34="","",INDEX($D$2:$D$5001,O34)) | T34: =IF(O34="","",INDEX($E$2:$E$5001,O34)) | V34: progress / do not exclude | W34: =COUNTIFS($H$2:$H$5001,$V34,$I$2:$I$5001,W$33) | X34: =COUNTIFS($H$2:$H$5001,$V34,$I$2:$I$5001,X$33) | Y34: =SUM(W34:X34)
